
  File "/nix/store/dfg63lldbvcj207iyr9z0xw21d8ax02n-python3.11-pip-24.0/lib/python3.11/site-packages/pip/_vendor/urllib3/response.py", line 561, in read
    data = self._fp_read(amt) if not fp_closed else b""
           ^^^^^^^^^^^^^^^^^^
  File "/nix/store/dfg63lldbvcj207iyr9z0xw21d8ax02n-python3.11-pip-24.0/lib/python3.11/site-packages/pip/_vendor/urllib3/response.py", line 527, in _fp_read
    return self._fp.read(amt) if amt is not None else self._fp.read()
           ^^^^^^^^^^^^^^^^^^
  File "/nix/store/dfg63lldbvcj207iyr9z0xw21d8ax02n-python3.11-pip-24.0/lib/python3.11/site-packages/pip/_vendor/cachecontrol/filewrapper.py", line 102, in read
    self.__buf.write(data)
  File "/nix/store/nmqxyr00in2arwrq5qd1qipsanz1yrn5-python3-3.11.10/lib/python3.11/tempfile.py", line 500, in func_wrapper
    return func(*args, **kwargs)
           ^^^^^^^^^^^^^^^^^^^^^
OSError: [Errno 122] Disk quota exceeded

During handling of the above exception, another exception occurred:

Traceback (most recent call last):
  File "/nix/store/dfg63lldbvcj207iyr9z0xw21d8ax02n-python3.11-pip-24.0/lib/python3.11/site-packages/pip/_internal/cli/base_command.py", line 180, in exc_logging_wrapper
    status = run_func(*args)
             ^^^^^^^^^^^^^^^
  File "/nix/store/dfg63lldbvcj207iyr9z0xw21d8ax02n-python3.11-pip-24.0/lib/python3.11/site-packages/pip/_internal/cli/req_command.py", line 245, in wrapper
    return func(self, options, args)
           ^^^^^^^^^^^^^^^^^^^^^^^^^
  File "/nix/store/dfg63lldbvcj207iyr9z0xw21d8ax02n-python3.11-pip-24.0/lib/python3.11/site-packages/pip/_internal/commands/install.py", line 377, in run
    requirement_set = resolver.resolve(
                      ^^^^^^^^^^^^^^^^^
  File "/nix/store/dfg63lldbvcj207iyr9z0xw21d8ax02n-python3.11-pip-24.0/lib/python3.11/site-packages/pip/_internal/resolution/resolvelib/resolver.py", line 179, in resolve
    self.factory.preparer.prepare_linked_requirements_more(reqs)
  File "/nix/store/dfg63lldbvcj207iyr9z0xw21d8ax02n-python3.11-pip-24.0/lib/python3.11/site-packages/pip/_internal/operations/prepare.py", line 552, in prepare_linked_requirements_more
    self._complete_partial_requirements(
  File "/nix/store/dfg63lldbvcj207iyr9z0xw21d8ax02n-python3.11-pip-24.0/lib/python3.11/site-packages/pip/_internal/operations/prepare.py", line 467, in _complete_partial_requirements
    for link, (filepath, _) in batch_download:
  File "/nix/store/dfg63lldbvcj207iyr9z0xw21d8ax02n-python3.11-pip-24.0/lib/python3.11/site-packages/pip/_internal/network/download.py", line 183, in __call__
    for chunk in chunks:
  File "/nix/store/dfg63lldbvcj207iyr9z0xw21d8ax02n-python3.11-pip-24.0/lib/python3.11/site-packages/pip/_internal/cli/progress_bars.py", line 53, in _rich_progress_bar
    for chunk in iterable:
  File "/nix/store/dfg63lldbvcj207iyr9z0xw21d8ax02n-python3.11-pip-24.0/lib/python3.11/site-packages/pip/_internal/network/utils.py", line 63, in response_chunks
    for chunk in response.raw.stream(
  File "/nix/store/dfg63lldbvcj207iyr9z0xw21d8ax02n-python3.11-pip-24.0/lib/python3.11/site-packages/pip/_vendor/urllib3/response.py", line 622, in stream
    data = self.read(amt=amt, decode_content=decode_content)
           ^^^^^^^^^^^^^^^^^^^^^^^^^^^^^^^^^^^^^^^^^^^^^^^^^
  File "/nix/store/dfg63lldbvcj207iyr9z0xw21d8ax02n-python3.11-pip-24.0/lib/python3.11/site-packages/pip/_vendor/urllib3/response.py", line 560, in read
    with self._error_catcher():
  File "/nix/store/nmqxyr00in2arwrq5qd1qipsanz1yrn5-python3-3.11.10/lib/python3.11/contextlib.py", line 158, in __exit__
    self.gen.throw(typ, value, traceback)
  File "/nix/store/dfg63lldbvcj207iyr9z0xw21d8ax02n-python3.11-pip-24.0/lib/python3.11/site-packages/pip/_vendor/urllib3/response.py", line 455, in _error_catcher
    raise ProtocolError("Connection broken: %r" % e, e)
pip._vendor.urllib3.exceptions.ProtocolError: ("Connection broken: OSError(122, 'Disk quota exceeded')", OSError(122, 'Disk quota exceeded'))
